<?xml version="1.0"?>

<robot name="clawbot">


	<material name="blue">
		<color rgba="0 0 0.8 1" />
	</material>

	<material name="white">
		<color rgba="1 1 1 1" />
	</material>

	<material name="green">
		<color rgba="0 0.5 0 1" />
	</material>

	<!-- BASE LINK -->
	<link name="base_link">
		<visual>
			<geometry>
				<box size="0.205 0.28 0.025"/>
			</geometry>
			<material name="white"/>
		</visual>
	</link>

	<!-- LEFT SIDE -->
	<link name="left_wheel_1">
		<visual>
			<geometry>
				<cylinder length="0.02" radius="0.05"/>
			</geometry>
			<origin rpy="1.570796327 0 0" xyz="0 0 0"/>
			<material name="green"/>
		</visual>
		<collision>
			<geometry>
				<cylinder length="0.02" radius="0.05"/>
			</geometry>
		</collision>
	</link>

	<joint name="base_to_left_wheel_1" type="continuous">
		<axis xyz="0 1 0"/>
		<parent link="base_link"/>
		<child link="left_wheel_1"/>
		<origin xyz="0.05125 0.15 0"/>
	</joint>

	<link name="left_wheel_2">
		<visual>
			<geometry>
				<cylinder length="0.02" radius="0.05"/>
			</geometry>
			<origin rpy="1.570796327 0 0" xyz="0 0 0"/>
			<material name="green"/>
		</visual>
	</link>

	<joint name="base_to_left_wheel_2" type="continuous">
		<axis xyz="0 1 0"/>
		<parent link="base_link"/>
		<child link="left_wheel_2"/>
		<origin xyz="-0.05125 0.15 0"/>
	</joint>


	<!-- RIGHT SIDE -->
	<link name="right_wheel_1">
		<visual>
			<geometry>
				<cylinder length="0.02" radius="0.05"/>
			</geometry>
			<origin rpy="1.570796327 0 0" xyz="0 0 0"/>
			<material name="green"/>
		</visual>
	</link>

	<joint name="base_to_right_wheel_1" type="continuous">
		<axis xyz="0 1 0"/>
		<parent link="base_link"/>
		<child link="right_wheel_1"/>
		<origin xyz="0.05125 -0.15 0"/>
	</joint>

	<link name="right_wheel_2">
		<visual>
			<geometry>
				<cylinder length="0.02" radius="0.05"/>
			</geometry>
			<origin rpy="1.570796327 0 0" xyz="0 0 0"/>
			<material name="green"/>
		</visual>
	</link>

	<joint name="base_to_right_wheel_2" type="continuous">
		<axis xyz="0 1 0"/>
		<parent link="base_link"/>
		<child link="right_wheel_2"/>
		<origin xyz="-0.05125 -0.15 0"/>
	</joint>

	<!-- LIDAR STAND -->
	<link name="left_stand">
		<visual>
			<geometry>
				<box size="0.025 0.02 0.33"/>
			</geometry>
			<origin rpy="0 0 0" xyz="0 0 0.1555"/>
			<material name="white"/>
		</visual>
	</link>

	<joint name="base_to_rleft_stand" type="fixed">
		<parent link="base_link"/>
		<child link="left_stand"/>
		<origin xyz="-0.05 0.1 0"/>
	</joint>

	<link name="right_stand">
		<visual>
			<geometry>
				<box size="0.025 0.02 0.33"/>
			</geometry>
			<origin rpy="0 0 0" xyz="0 0 0.1555"/>
			<material name="white"/>
		</visual>
	</link>

	<joint name="base_to_right_stand" type="fixed">
		<parent link="base_link"/>
		<child link="right_stand"/>
		<origin xyz="-0.05 -0.1 0"/>
	</joint>

	<link name="main_stand">
		<visual>
			<geometry>
				<box size="0.06 0.32 0.01"/>
			</geometry>
			<origin rpy="0 0 0" xyz="0 0 0"/>
			<material name="white"/>
		</visual>
	</link>

	<joint name="base_to_main_stand" type="fixed">
		<parent link="base_link"/>
		<child link="main_stand"/>
		<origin xyz="-0.05 0 0.32"/>
	</joint>


	<!-- LIDAR -->
	<link name="base_laser">
		<visual>
			<geometry>
				<box size="0.05 0.05 0.05"/>
			</geometry>
			<origin rpy="0 0 0" xyz="0 0 0"/>
			<material name="blue"/>
		</visual>
	</link>

	<joint name="main_stand_base_laser" type="fixed">
		<parent link="main_stand"/>
		<child link="base_laser"/>
		<origin xyz="0 0 0.025"/>
	</joint>


</robot>